{
  "size": [5, 6, 5],
  "constraints": {
    "valid_ground": ["game:grass", "game:dirt"]
  },
  "options": {
    "create_foundation": true,
    "foundation_material": "game:stone"
  },
  "palette": [
    "game:stone_bricks",
    "game:planks_oak",
    "game:glass",
    "game:log_oak",
    "game:door"
  ],
  "blocks": [
    {"pos": [0, 0, 0], "state": 0}, {"pos": [1, 0, 0], "state": 0}, {"pos": [2, 0, 0], "state": 0}, {"pos": [3, 0, 0], "state": 0}, {"pos": [4, 0, 0], "state": 0},
    {"pos": [0, 0, 1], "state": 0}, {"pos": [4, 0, 1], "state": 0},
    {"pos": [0, 0, 2], "state": 0}, {"pos": [4, 0, 2], "state": 0},
    {"pos": [0, 0, 3], "state": 0}, {"pos": [4, 0, 3], "state": 0},
    {"pos": [0, 0, 4], "state": 0}, {"pos": [1, 0, 4], "state": 0}, {"pos": [2, 0, 4], "state": 0}, {"pos": [3, 0, 4], "state": 0}, {"pos": [4, 0, 4], "state": 0},

    {"pos": [0, 1, 0], "state": 3}, {"pos": [4, 1, 0], "state": 3},
    {"pos": [0, 1, 4], "state": 3}, {"pos": [4, 1, 4], "state": 3},
    {"pos": [1, 1, 0], "state": 1}, {"pos": [2, 1, 0], "state": 1}, {"pos": [3, 1, 0], "state": 1},
    {"pos": [0, 1, 1], "state": 1}, {"pos": [4, 1, 1], "state": 1},
    {"pos": [0, 1, 2], "state": 2}, {"pos": [4, 1, 2], "state": 1},
    {"pos": [0, 1, 3], "state": 1}, {"pos": [4, 1, 3], "state": 1},
    {"pos": [1, 1, 4], "state": 1}, {"pos": [2, 1, 4], "state": 4}, {"pos": [3, 1, 4], "state": 1},

    {"pos": [0, 2, 0], "state": 3}, {"pos": [4, 2, 0], "state": 3},
    {"pos": [0, 2, 4], "state": 3}, {"pos": [4, 2, 4], "state": 3},
    {"pos": [1, 2, 0], "state": 1}, {"pos": [2, 2, 0], "state": 2}, {"pos": [3, 2, 0], "state": 1},
    {"pos": [0, 2, 1], "state": 1}, {"pos": [4, 2, 1], "state": 1},
    {"pos": [0, 2, 2], "state": 2}, {"pos": [4, 2, 2], "state": 1},
    {"pos": [0, 2, 3], "state": 1}, {"pos": [4, 2, 3], "state": 1},
    {"pos": [1, 2, 4], "state": 1}, {"pos": [2, 2, 4], "state": 4}, {"pos": [3, 2, 4], "state": 1},

    {"pos": [0, 3, 0], "state": 0}, {"pos": [1, 3, 0], "state": 0}, {"pos": [2, 3, 0], "state": 0}, {"pos": [3, 3, 0], "state": 0}, {"pos": [4, 3, 0], "state": 0},
    {"pos": [0, 3, 1], "state": 0}, {"pos": [4, 3, 1], "state": 0},
    {"pos": [0, 3, 2], "state": 0}, {"pos": [4, 3, 2], "state": 0},
    {"pos": [0, 3, 3], "state": 0}, {"pos": [4, 3, 3], "state": 0},
    {"pos": [0, 3, 4], "state": 0}, {"pos": [1, 3, 4], "state": 0}, {"pos": [2, 3, 4], "state": 0}, {"pos": [3, 3, 4], "state": 0}, {"pos": [4, 3, 4], "state": 0},
    {"pos": [1, 3, 1], "state": 1}, {"pos": [2, 3, 1], "state": 1}, {"pos": [3, 3, 1], "state": 1},
    {"pos": [1, 3, 2], "state": 1}, {"pos": [2, 3, 2], "state": 1}, {"pos": [3, 3, 2], "state": 1},
    {"pos": [1, 3, 3], "state": 1}, {"pos": [2, 3, 3], "state": 1}, {"pos": [3, 3, 3], "state": 1}
  ],
  "entities": [
    {
      "id": "game:villager",
      "pos": [2, 1, 2]
    }
  ]
}
