{
  "size": [5, 25, 5],
  "constraints": {
    "valid_ground": ["game:grass", "game:dirt"],
    "deny_liquid": true
  },
  "palette": [
    "game:log_oak",
    "game:leaves"
  ],
  "blocks": [
    {"pos": [2, 0, 2], "state": 0}, {"pos": [3, 0, 2], "state": 0}, {"pos": [2, 0, 3], "state": 0}, {"pos": [3, 0, 3], "state": 0},
    {"pos": [2, 1, 2], "state": 0}, {"pos": [3, 1, 2], "state": 0}, {"pos": [2, 1, 3], "state": 0}, {"pos": [3, 1, 3], "state": 0},
    {"pos": [2, 2, 2], "state": 0}, {"pos": [3, 2, 2], "state": 0}, {"pos": [2, 2, 3], "state": 0}, {"pos": [3, 2, 3], "state": 0},
    {"pos": [2, 3, 2], "state": 0}, {"pos": [3, 3, 2], "state": 0}, {"pos": [2, 3, 3], "state": 0}, {"pos": [3, 3, 3], "state": 0},
    {"pos": [2, 4, 2], "state": 0}, {"pos": [3, 4, 2], "state": 0}, {"pos": [2, 4, 3], "state": 0}, {"pos": [3, 4, 3], "state": 0},
    {"pos": [2, 5, 2], "state": 0}, {"pos": [3, 5, 2], "state": 0}, {"pos": [2, 5, 3], "state": 0}, {"pos": [3, 5, 3], "state": 0},
    {"pos": [2, 6, 2], "state": 0}, {"pos": [3, 6, 2], "state": 0}, {"pos": [2, 6, 3], "state": 0}, {"pos": [3, 6, 3], "state": 0},
    {"pos": [2, 7, 2], "state": 0}, {"pos": [3, 7, 2], "state": 0}, {"pos": [2, 7, 3], "state": 0}, {"pos": [3, 7, 3], "state": 0},
    {"pos": [2, 8, 2], "state": 0}, {"pos": [3, 8, 2], "state": 0}, {"pos": [2, 8, 3], "state": 0}, {"pos": [3, 8, 3], "state": 0},
    {"pos": [2, 9, 2], "state": 0}, {"pos": [3, 9, 2], "state": 0}, {"pos": [2, 9, 3], "state": 0}, {"pos": [3, 9, 3], "state": 0},
    {"pos": [2, 10, 2], "state": 0}, {"pos": [3, 10, 2], "state": 0}, {"pos": [2, 10, 3], "state": 0}, {"pos": [3, 10, 3], "state": 0},
    {"pos": [2, 11, 2], "state": 0}, {"pos": [3, 11, 2], "state": 0}, {"pos": [2, 11, 3], "state": 0}, {"pos": [3, 11, 3], "state": 0},
    {"pos": [2, 12, 2], "state": 0}, {"pos": [3, 12, 2], "state": 0}, {"pos": [2, 12, 3], "state": 0}, {"pos": [3, 12, 3], "state": 0},
    {"pos": [2, 13, 2], "state": 0}, {"pos": [3, 13, 2], "state": 0}, {"pos": [2, 13, 3], "state": 0}, {"pos": [3, 13, 3], "state": 0},
    {"pos": [2, 14, 2], "state": 0}, {"pos": [3, 14, 2], "state": 0}, {"pos": [2, 14, 3], "state": 0}, {"pos": [3, 14, 3], "state": 0},
    {"pos": [2, 15, 2], "state": 0}, {"pos": [3, 15, 2], "state": 0}, {"pos": [2, 15, 3], "state": 0}, {"pos": [3, 15, 3], "state": 0},
    {"pos": [2, 16, 2], "state": 0}, {"pos": [3, 16, 2], "state": 0}, {"pos": [2, 16, 3], "state": 0}, {"pos": [3, 16, 3], "state": 0},
    {"pos": [2, 17, 2], "state": 0}, {"pos": [3, 17, 2], "state": 0}, {"pos": [2, 17, 3], "state": 0}, {"pos": [3, 17, 3], "state": 0},
    {"pos": [2, 18, 2], "state": 0}, {"pos": [3, 18, 2], "state": 0}, {"pos": [2, 18, 3], "state": 0}, {"pos": [3, 18, 3], "state": 0},

    {"pos": [1, 18, 1], "state": 1}, {"pos": [2, 18, 1], "state": 1}, {"pos": [3, 18, 1], "state": 1}, {"pos": [4, 18, 1], "state": 1},
    {"pos": [1, 18, 4], "state": 1}, {"pos": [2, 18, 4], "state": 1}, {"pos": [3, 18, 4], "state": 1}, {"pos": [4, 18, 4], "state": 1},
    {"pos": [1, 18, 2], "state": 1}, {"pos": [4, 18, 2], "state": 1},
    {"pos": [1, 18, 3], "state": 1}, {"pos": [4, 18, 3], "state": 1},

    {"pos": [0, 19, 2], "state": 1}, {"pos": [5, 19, 2], "state": 1},
    {"pos": [0, 19, 3], "state": 1}, {"pos": [5, 19, 3], "state": 1},
    {"pos": [2, 19, 0], "state": 1}, {"pos": [3, 19, 0], "state": 1},
    {"pos": [2, 19, 5], "state": 1}, {"pos": [3, 19, 5], "state": 1},

    {"pos": [1, 20, 1], "state": 1}, {"pos": [2, 20, 1], "state": 1}, {"pos": [3, 20, 1], "state": 1}, {"pos": [4, 20, 1], "state": 1},
    {"pos": [1, 20, 2], "state": 1}, {"pos": [2, 20, 2], "state": 1}, {"pos": [3, 20, 2], "state": 1}, {"pos": [4, 20, 2], "state": 1},
    {"pos": [1, 20, 3], "state": 1}, {"pos": [2, 20, 3], "state": 1}, {"pos": [3, 20, 3], "state": 1}, {"pos": [4, 20, 3], "state": 1},
    {"pos": [1, 20, 4], "state": 1}, {"pos": [2, 20, 4], "state": 1}, {"pos": [3, 20, 4], "state": 1}, {"pos": [4, 20, 4], "state": 1},

    {"pos": [2, 21, 2], "state": 1}, {"pos": [3, 21, 2], "state": 1},
    {"pos": [2, 21, 3], "state": 1}, {"pos": [3, 21, 3], "state": 1}
  ]
}
